## 자바 예외처리의 기본

- 자바에서 말하는 예외
    
    프로그램 실행 중에 발생하는 ‘예외적인 상황’을 줄여서 ‘예외’라 한다. 즉 예외는 단순한 문법 오류가 아닌 실행 중간에 발생하는 ‘정상적이지 않은 상황’을 뜻한다.
    
    ```java
    import java.util.Scanner;
    
    class ExceptionCase { 
        public static void main(String[] args) {
            Scanner kb = new Scanner(System.in);
        
            System.out.print("a/b... a? ");
            int n1 = kb.nextInt(); // int 형 정수 입력
            
            System.out.print("a/b... b? ");
            int n2 = kb.nextInt(); // int 형 정수 입력
            
            System.out.printf("%d / %d = %d \\n", n1, n2, n1/n2);
            System.out.println("Good bye~~!");
        }
    }
    ```
    
    위 예제 코드는 문법적으로는 문제가 없다. 문제는 나누는 수가 0이 될 수 없음에도 불구하고 0을 입력한 프로그램 사용자에 있다. 그러고 이러한 상황을 가리켜 ‘예외’라 한다. 예외 발생 순간에 프로그램이 종료된 사실에 주목하자. 그리고 친절한 상황 설명은 아니지만 출력된 문장을 통해서 다음 사실 정도는 알 수 있다.
    
    “0으로 / 연산을 하여 java.lang.ArithmeticException 예외가 발생하였다.”
    
    이는 가상머신이 예외 상황을 처리하는 방식이다. 즉 가상머신은 예외가 발생하면 그 내용을 간단히 출력하고 프로그램을 종료해버린다. 참고로 다른 예제도 있다. 숫자가 아닌 문자를 입력하는 행위도 ‘예외’이다. 숫자를 대신하여 문자를 입력한 결과는 프로그램이 종료가 되버린다. 그러나 이는 우리가 원하는 방식의 예외 처리가 아니다. 최소한 다음과 같이 예외의 원인을 설명하고,
    
    “숫자를 입력해야 합니다. 다시 실행해주세요.”
    
    라는 문장을 뛰우는 것이 우리가 생각하는 예외일것이다.
    
- 예외를 처리를 위한 try ~ catch
    
    앞서 예외가 발생하는 두 가지 상황을 보였는데, 이때 출력된 메시지에서 다음 클래스의 이름을 확인할 수 있다.
    
    java.lang.ArithmeticExcepition
    
    → 수학 연산에서의 오류 상황을 의미하는 예외 클래스
    
    java.util.InputMismatchException
    
    → 클래스 Scanner를 통한 값의 입력에서의 오류 상황을 의미하는 예외 클래스
    
    이렇듯 자바는 상황별로 그 상황을 알리기 위한 클래스를 정의하고 있다. 이러한 클래스를 ‘예외 클래스’ 라고 한다.
    
    예외를 처리할 때에는 try ~ catch문을 사용하는데, 이 문장의 기본 구조는 다음과 같다.
    
    ```java
    try {
    	...관찰 영역...
    }
    catch(Exception name) {
    	...처리 영역...
    }
    ```
    
    이렇듯 try ~ catch문은 try 영역과 catch 영역으로 구분 되는데, 이 둘은 하나의 문자이므로 항상 연결되어 있어야 한다.
    
    ```java
    try {
    	...관찰 영역...
    }
    catch(ArithmeticExcepition e) {
    	...처리 영역...
    }
    ```
    
    try 영역의 실행 중간에 예외 상황이 만들어지고 이로 인해 가상머신이 ArithmeticExcepition 인스턴스를 생성하면, 이 인스턴스는 메소드를 호출하듯이 catch 구문의 매개변수 e에 전달이 된다. 그러면 가상머신은 catch 구문 안에서 무엇을 하든 상관없이 예외가 처리된 것으로 간주하고 실행을 이어나간다.
    
    ```java
    import java.util.Scanner;
    
    class ExceptionCase2 { 
        public static void main(String[] args) {
            Scanner kb = new Scanner(System.in);
    
            try {
                System.out.print("a/b... a? ");
                int n1 = kb.nextInt();
                
                System.out.print("a/b... b? ");
                int n2 = kb.nextInt();
            
                System.out.printf("%d / %d = %d \\n", n1, n2, n1/n2);
            }
            catch(ArithmeticException e) {
                System.out.println(e.getMessage());
            }
    
            System.out.println("Good bye~~!");
        }
    }
    ```
    
    위 예제에서 발생하는 문장은 다음과 같다. n2가 0인 상태에서 나눗셈을 진행하는 순간에 예외가 발생한다.
    
    ```java
    System.out.printf("%d / %d = %d \\n", n1, n2, n1 / n2); // 예외 발생 지점
    ```
    
    그러면 이 순간에 가상머신 ArithmeticExcepition 인스턴스를 생성한다. 그리고 예외 발생 지점을 감싸는 try 영역에 이어서 등장하는 catch 영역에서 이 인스턴스를 인자로 받을 수 있는지 확인하고, 받을 수 있으면 catch 영역으로 인스턴스를 전달한다.
    
    그리고 예외에는 getMessage()라는 메소드가 있는데 일단 이 메소드는 예외의 원인을 담고 있는 문자열을 반환한다고 알고 있자.
    
- try로 감싸야 할 영역의 결정
    
    다음의 try~catch문에서 숫자 2의 위치에서 예외가 발생하고 catch 영역에서 이 예외가 처리가 되면,
    
    ```java
    try {
    	1. ...
    	2. 예외 발생 지점
    	3. ...
    }
    catch(Exception e) {
    	...
    }
    4. 예외 처리 이후 실행 지점
    ```
    
    숫자 3의 위치에서 실행을 이어가는 것이 아닌 4의 위치에서 실행을 이어 나간다. 이러한 예외 처리 이후의 실행 특성은, 관련이 있는 작업들을 하나로 묶는데 도움이 된다.
    
    ```java
    import java.util.Scanner;
    
    class ExceptionCase3 { 
        public static void main(String[] args) {
            Scanner kb = new Scanner(System.in);
    
            System.out.print("a/b... a? ");
            int n1 = kb.nextInt();
                
            System.out.print("a/b... b? ");
            int n2 = kb.nextInt();
            
            System.out.printf("%d / %d = %d \\n", n1, n2, n1/n2);
            System.out.println("Good bye~~!");
        }
    }
    ```
    
    여기서 R 문자를 입력하면 InputMismatchException 오류가 난다. 이 오류가 날 수 있는 문장은 다음과 같다.
    
    ```java
    int n1 = kb.nextInt();
    int n2 = kb.nextInt();
    ```
    
    따라서 이들 각각의 대해 try ~ catch문을 구성하는 것도 생각해 볼 수 있다. 그러나 변수 n1의 값이 적절히 들어오지 않는다면, 변수 n2의 값을 입력받는 것도, / 연산을 진행하는 것도 의미가 없다. 즉 다음 문장들은 하나의 작업으로 볼 수 있다.
    
    ```java
    System.out.print("a/b... a? ");
    int n1 = kb.nextInt();
     
    System.out.print("a/b... b? ");
    int n2 = kb.nextInt();
    
    System.out.printf("%d / %d = %d \\n", n1, n2, n1/n2);
    ```
    
    따라서 이를 진행하는 과정에서 어느 한 곳에서 예외가 발생하면 나머지 부분을 건너뛰는 것이 적절하다.
    
    ```java
    import java.util.Scanner;
    import java.util.InputMismatchException;
    
    class ExceptionCase4 { 
        public static void main(String[] args) {
            Scanner kb = new Scanner(System.in);
    
            try {
                System.out.print("a/b... a? ");
                int n1 = kb.nextInt();
                
                System.out.print("a/b... b? ");
                int n2 = kb.nextInt();
            
                System.out.printf("%d / %d = %d \\n", n1, n2, n1/n2);
            }
            catch(InputMismatchException e) {
                e.getMessage();
            }
    
            System.out.println("Good bye~~!");
        }
    }
    ```
    
- 둘 이상의 예외를 처리하기 위한 구성
    
    나눗셈 과정에서는 두 가지 예외의 발생 가능성이 있다.
    
    ```java
    java.util.InputMismatchException;
    java.util.ArithmeticExcepition;
    ```
    
    따라서 이 둘에 대한 모두 예외 처리를 하고자 한다면, 다음에 보이는 바와 같이 catch 구문 둘을 이어서 구성하면 된다.
    
    ```java
    import java.util.Scanner;
    import java.util.InputMismatchException;
    
    class ExceptionCase5 { 
        public static void main(String[] args) {
            Scanner kb = new Scanner(System.in);
    
            try {
                System.out.print("a/b... a? ");
                int n1 = kb.nextInt();
                
                System.out.print("a/b... b? ");
                int n2 = kb.nextInt();
            
                System.out.printf("%d / %d = %d \\n", n1, n2, n1/n2);
            }
            catch(ArithmeticException e) {
                e.getMessage();
            }
            catch(InputMismatchException e) {
                e.getMessage();
            }
    
            System.out.println("Good bye~~!");
        }
    }
    ```
    
    예제 보이듯이 catch 구문을 얼마든지 이어서 구성할 수 있다. 그런데 자바 7부터는 다음과 같이 하나의 catch 구문 안에서 둘 이상의 예외를 처리하는 것도 가능하다.
    
    ```java
    import java.util.Scanner;
    import java.util.InputMismatchException;
    
    class ExceptionCase6 { 
        public static void main(String[] args) {
            Scanner kb = new Scanner(System.in);
    
            try {
                System.out.print("a/b... a? ");
                int n1 = kb.nextInt();
                
                System.out.print("a/b... b? ");
                int n2 = kb.nextInt();
            
                System.out.printf("%d / %d = %d \\n", n1, n2, n1/n2);
            }
            catch(ArithmeticException | InputMismatchException e) {
                e.getMessage();
            }
    
            System.out.println("Good bye~~!");
        }
    }
    ```
    
    따라서 상황 별 예외의 처리 방식이 다르지 않을 경우, 위와 같이 하나의 catch 구문 안에서 모든 예외가 처리될 수 있도록 묶는 것도 유용한 선택이 될 수 있다.
    
- Throwable 클래스와 예외처리의 책임 전가
    
    자바의 최상의 클래스인 java.lang.Object를 제외하고 예외 클래스의 최상의 클래스는 다음과 같다.
    
    ```java
    java.lang.Throwable
    ```
    
    그리고 이 클래스에는 발생한 예외의 정보를 알 수 있는 메소드가 정의되어 있는데, 대표적인 메소드 둘은 다음과 같다.
    
    ```java
    public String getMessage()
    ```
    
    → 예외의 원인을 담고 있는 문자열을 반환
    
    ```java
    public void printStackTrace()
    ```
    
    → 예외가 발생한 위치와 호출된 메소드의 정보를 출력
    
    그럼 printStackTrace 메소드의 기능 확인을 위해 다음 예제를 실행해보자. 참고로 이는 예외가 발생할 수밖에 없는 예제이다.
    
    ```java
    class ExceptionMessage { 
        public static void md1(int n) {
            md2(n, 0);     // 아래의 메소드 호출
        }
        public static void md2(int n1, int n2) {
            int r = n1 / n2;    // 예외 발생 지점
        }
        public static void main(String[] args) {
            md1(3);
            System.out.println("Good bye~~!");
        }
    }
    ```
    
    위 메소드 호출 흐름은 다음과 같다. main → md1 → md2 그리고 예외는 md2에서 발생하였다. 그런데 md2에서 해당 예외를 처리하지 않았다. 이러한 경우 가상머신은 md2를 호출한 md1에게 예외처리의 책임을 넘긴다. 그런데 md1도 예외처리를 하지 않았다. 따라서 가상머신은 md1을 호출한 main에게 예외처리의 책임을 넘긴다.
    
    이렇듯 예외는 처리되지 않으면 그 책임이 넘어간다. 그리고 그 끝은 main이다. 그런데 main도 예외처리를 하지 않았다면 가상머신이 대신 예외를 처리한다.
    
    이번에는 발생하는 예외를 main 메소드에서 처리하는 방법을 보이겠다.
    
    ```java
    class ExceptionMessage2 { 
        public static void md1(int n) {
            md2(n, 0);
        }
        public static void md2(int n1, int n2) {
            int r = n1 / n2;
        }
        public static void main(String[] args) {
            try {
                md1(3);
            }
            catch(Throwable e) {
                e.printStackTrace();
            }
            
            System.out.println("Good bye~~!");
        }
    }
    ```
    
    위에서 보이듯이 md1에서 넘어오는 예외를 처리하기 위한 try ~ catch문이다. 이렇게 md1에서 넘어오는 예외을 처리하기 위해서는 md1 호출문을 try~catch문으로 감싸면 된다.
    
    ```java
    try {
        md1(3);
    }
    catch(Throwable e) {
        e.printStackTrace();
    }
    ```
    
    그런데 실제로 넘어오는 예외는 Throwable가 아니다. 그러나 모든 예외 클래스는 Throwable을 상속하므로 상속 관계에 의해 md2에서 발행한 예외를 위와 같이 처리할 수도 있다. (이는 좋은 예외처리가 아니다.)
    
- 예외 상황을 알리기 위해 정의된 클래스의 종류
    
    배열 접근에 잘못된 인덱스 값을 사용해서 발생하는 ArrayIndexOutOfBoundsException 예외의 상황을 다음 예제를 통해서 보이겠다.
    
    ```java
    class ArrayIndexOutOfBounds { 
        public static void main(String[] args) {
            int[] arr = {1, 2, 3};    
            for(int i = 0; i < 4; i++)
                System.out.println(arr[i]);
        }
    }
    ```
    
    ```java
    1
    2
    3
    Exception in thread "main" java.lang.ArrayIndexOutBoundsException: 3
    				at ArrayIndexOutBoundsException.main(ArrayIndexOutBoundsException.java:5)
    ```
    
    다음은 허용할 수 없는 형 변환을 강제로 진행하는 발생하는 ClassCastException 예외의 상황을 보여준다.
    
    ```java
    class Board { }
    class PBoard extends Board { }
    
    class ClassCast { 
        public static void main(String[] args) {
             Board pbd1 = new PBoard();
             PBoard pbd2 = (PBoard)pbd1;    // OK!
        
             System.out.println(".. intermediate location .. ");
             Board ebd1 = new Board();
             PBoard ebd2 = (PBoard)ebd1;    // Exception!
        }
    }
    ```
    
    ```
    .. intermediate location .. 
    Exception in thread "main" java.lang.ClassCastException: class Board cannot be cast to class PBoard (Board and PBoard are in unnamed module of loader 'app')
    	at Main.main(Main.java:11)
    ```
    
    다음은 null이 저정된 참조변수를 대상으로 메소드를 호출할 때 발생하는 NullPointerException 예외의 상황을 보여준다.
    
    ```java
    class NullPointer {
        public static void main(String[] args) {
            String str = null;
            System.out.println(str);    // null 출력
            int len = str.length();    // Exception!
        }
    }
    ```
    
    ```
    null
    Exception in thread "main" java.lang.NullPointerException
    	at NullPointer.main(Main.java:7)
    ```
    

## 예외처리에 대한 나머지 설명들

- 예외 클래스의 구분
    
    예외 클래스의 최상의 클래스 Throwable임을 앞서 설명하였다. 그런데 이를 상속하는 예외 클래스는 다음과 같이 세 부류로 나뉜다.
    
    - Error 클래스를 상속하는 예외 클래스
    - Exception 클래스를 상속하는 예외 클래스
    - RuntimeException 클래스를 상속하는 예외 클래스 → RuntimeException 클래스는 Exception 클래스를 상속한다.
    
    이 중에서 ‘Error 클래스를 상속하는 예외 클래스’의 예와 그 발생 상황을 정리하면 다음과 같다.
    
    - VirtualMachineError - 가상머신에 심각한 오류 발생
    - IOError - 입출력 관련해서 코드 수준 복구가 불가능한 오류 발생
    
    구체적인 예를 들면, 자바 프로그램이 임의의 파일에 저장된 데이터를 읽는 중에 갑자기 하드디스크에 물리적 오류가 발생하여 더 이상 파일에 저장된 데이터를 읽을 수 없는 상황이 생길 수 있다. 그리고 이러한 수준의 상황에서 발생하는 것이 IOError 예외이다. 즉 Error 클래스를 상속하는 예외는 처리의 대상이 아니다. 바꾸어 말하면 처리할 수 있는 예외가 아니다. 따라서 이런 유형의 예외가 발생하면 그냥 프로그램이 종료되도록 놔두고 이후에 원일을 파악하는 과정이 이어져야 한다.
    
    - VirtualMachineError를 상속하는 OutOfMemoryError
        
        OutOfMemoryError은 메모리 공간이 부족한 상황에서 발생하는 예외이다. 따라서 이 예외가 발생하면 메모리를 비효율적으로 또는 부적절하게 사용하는 부분의 코드를 수정해야 한다.
        
    
    이어서 ‘RuntimeException 클래스에 상속하는 예외 클래스’에 대해 설명하고자 하는데, 앞서 보였던 모든 예외 클래스가 바로 이 예외에 해당된다.
    
    - ArithmeticException
    - ClassCaseException
    - IndexOutOfBoundsException
    - NegativeArraySizeException 배열 생성시 길이를 음수로 지정하는 예외의 발생
    - NullPointerException
    - ArrayStoreException 배열에 적절치 않은 인스턴스를 저장하는 예외의 발생
    
    마지막으로 ‘Exception 클래스를 상속하는 예외 클래스’가 있는데, RuntimeException 클래스를 상속하는 예외 클래스는 이 부류에서 제외한다. 즉 지금부터 설명하는 특서은 RuntimeException 클래스를 직접 혹은 간접으로 상속하지 않고 Exception 클래스만 상속하는 예외클래스에 해당하는 내용이다.
    
    그 수로만 따지면 Exception 클래스를 상속하는 예외 클래스 가장 많다.
    
- Exception을 상속하는 예외 클래스의 예외처리
    
    Exception을 상속하는 예외 클래스 중에서 비교적 빨리 접하게 될 클래스는 다음과 같다.
    
    java.io.IOException
    
    그래서 이 예외의 발생 가능성이 있는 코드를 가지고 설명을 이어가겠다. 참고로 다음 예제의 코드를 세세히 이해할 필요는 없다. 지금은 어느 지점에서 어느 예외가 발생하는지 정도만 확인하면 된다.
    
    ```java
    import java.nio.file.Path;
    import java.nio.file.Paths;
    import java.nio.file.Files;
     
    import java.io.BufferedWriter;
    import java.io.IOException;
     
     
    class IOExceptionCase { 
        public static void main(String[] args) {
            Path file = Paths.get("C:\\\\javastudy\\\\Simple.txt");
            BufferedWriter writer = null;
    
            try {
                // 아래 문장에서 IOException 발생 가능
                writer = Files.newBufferedWriter(file);
    
                writer.write('A');     // IOException 발생 가능
                writer.write('Z');     // IOException 발생 가능
    
                if(writer != null)
                    writer.close();     // IOException 발생 가능
            } 
            catch(IOException e) {
                e.printStackTrace();
            }
        }
    }
    ```
    
    위 예제는 다음 경로의 파일을 생성해서, 그 안에 두 개의 문자를 저장하고 끝을 맺는 예제이다.
    
    ```java
    C:\\javastudy\\Simple.txt
    ```
    
    그런데 try ~ catch문을 지우고 다음의 상태에서 컴파일을 해보자. 그러면 컴파일 오류가 발생하는 것을 확인할 수 있다.
    
    ```java
    import java.nio.file.Path;
    import java.nio.file.Paths;
    import java.nio.file.Files;
     
    import java.io.BufferedWriter;
    import java.io.IOException;
     
    class IOExceptionCase2 { 
        public static void main(String[] args) {
            Path file = Paths.get("C:\\\\javastudy\\\\Simple.txt");
            BufferedWriter writer = null;
            writer = Files.newBufferedWriter(file);     // IOException 발생 가능
            writer.write('A');     // IOException 발생 가능
            writer.write('Z');     // IOException 발생 가능
    
            if(writer != null)
                writer.close();     // IOException 발생 가능  
        }
    }
    ```
    
    try ~ catch문을 지워서 예외처리를 생략한 것뿐인데 컴파일 오류가 발생한다. 그것도 IOException 예외 발생이 가능한 문장에서 오류가 발생한다. 정확히는 IOException 예외 발생 가능성이 있는 ‘메소드 호출문’에서 오류가 발생하였다.
    
    앞서 언급한 Error 클래스를 상속하는 예외나 RuntimeException 클래스를 상속하는 예외의 경우 예외의 처리는 선택이다. 그러나 `Exception 클래스를 상속하는 예외는 try ~ catch문으로 처리하거나 다른 영역으로 넘긴다고 반드시 명시해야 한다`. 그럼 이와 관련하여 다음 예제를 보자.
    
    ```java
    import java.nio.file.Path;
    import java.nio.file.Paths;
    import java.nio.file.Files; 
    import java.io.BufferedWriter;
    import java.io.IOException;
     
    class IOExceptionCase3 { 
        public static void main(String[] args) {
            try {
                md1();
            }
            catch(IOException e) {
                e.printStackTrace();
            }
        }
    
        public static void md1() throws IOException {
            md2();
        }
    
        public static void md2() throws IOException {
            Path file = Paths.get("C:\\\\javastudy\\\\Simple.txt");
            BufferedWriter writer = null;
            writer = Files.newBufferedWriter(file);    // IOException 발생 가능
            writer.write('A');     // IOException 발생 가능
            writer.write('Z');     // IOException 발생 가능
    
            if(writer != null)
                writer.close();     // IOException 발생 가능
        }
    }
    ```
    
    위 예제의 메소드 호출 과정은 다음과 같다.
    
    main → md1 → m2
    
    이 중에서 md2 내에서 IOException 예외가 발생할 수 있다. 그런데 IOException은 Exception을 상속한다. 따라서 이에 대해 다음과 같이 try ~ catch문을 작성하거나,
    
    ```java
    public static void md2() {
    	Path file = Paths.get("C:\\\\javastudy\\\\Simple.txt");
    	try {
    		...
    	}
    	catch(IOException e) {
    		e.printStackTrace();
    	}
    }
    ```
    
    아니면 다음과 같이 예외의 처리를, 이 메소드를 호출한 메소드에게 넘긴다는 표시를 해야 한다.
    
    ```java
    public static void md1() throws IOException { // IOException 예외 발생하면 넘긴다.
    	md2();
    }
    ```
    
    마지막으로 md1을 호출하는 main 메소드를 보자. 이 메소드에서 IOException 예외가 전달될 수 있는 md1을 호출하므로, main 메소드의 선택도 다음 둘 중 하나이다.
    
    - try ~ catch문을 이용해 IOException을 직접 처리하거나
    - throws IOException 선언을 추가해서 예외의 처리를 넘기거나
    
    main 메소드도 예외를 넘기면, 이 예외는 main을 호출한 가상머신에게 넘어간다. 그러면 우리가 앞서 본 것처럼 프로그램은 종료가 된다.
    
    끝으로 throws 선언을 통해서, 둘 이상의 예외에 대해 그 처리를 넘긴다는 표시를 할 수 있다는 사실도 알아 두자. 예를 들어 다음과 같다.
    
    ```java
    public void simpleWrite() throws IOException, IndexOutofBoundsException {
    	...
    }
    ```
    
    정리하면 이렇다. Error를 상속하거나 RuntimeException을 상속하는 예외의 발생은 코드 작성 과정에서 특별히 무언가를 하지 않아도 된다. 그러나 Exception을 상속하는 예외의 발생에 대해서는 try ~ catch문을 통해서 예외를 처리하거나 throws 선언을 통해서 예외의 처리를 넘긴다는 표시를 꼭 해야 한다. 그리고 앞으로 배우게 될 메소드 중에는 예외를 전달하는 메소드의 수가 적지 않은데, 그 메소드들이 전달하는 예외 대부분은 Exception을 상속한다. 따라서 이러한 메소드의 호출을 위해서는 지금 설명한 것처럼 예외를 던지거나, 처리하는 코드를 넣어주어여야 한다. 이것이 자바에서 예외처리가 필수인 이유다.
    
- 프로그래머가 정의하는 예외
    
    프로그래머가 직접 예외 클래스를 정의하고 이를 기반으로 특정 상황에서 예외가 발생하도록 할 수도 있다. 프로그래머가 정의하는 예외 클래스의 예는 다음과 같은데, 이 클래스의 핵심은 Exception을 상속하는데 있다.
    
    ```java
    class ReadAgeException extends Exception { // Exception을 상속하는 것이 핵심 
    	public ReadAgeException() {
    		super("유효하지 않은 나이가 입력되었습니다.");
    	}
    }
    ```
    
    위의 클래스는 Exception을 상속받는것을 빼면 일반 클래스와 다른 점은 없다. 그리고 생성자에서는 상위 클래스의 생성자를 호출하면서 예외 상황에 대한 설명을 담고 있는 문자열을 전달하는데, 이 문자열은 앞서 보였던 Throwable 클래스에 정의된 다음 메소드 호출 시 반환이 된다.
    
    ```java
    public String getMessage()
    ```
    
    이를 활용한 다음 예제를 보자.
    
    ```java
    import java.util.Scanner;
    
    class ReadAgeException extends Exception {
        public ReadAgeException() {
            super("유효하지 않은 나이가 입력되었습니다.");
        }
    }
    
    class MyExceptionClass {
        public static void main(String[] args) {
            System.out.print("나이 입력: ");
        
            try {
                int age = readAge();
                System.out.printf("입력된 나이: %d \\n", age);
            }
            catch(ReadAgeException e) {
                System.out.println(e.getMessage());
            }
        }
        
        public static int readAge() throws ReadAgeException {
            Scanner kb = new Scanner(System.in);
            int age = kb.nextInt();
            
            if(age < 0)
                throw new ReadAgeException();
    
            return age;
        }
    }
    ```
    
    만약에 음수를 입력했다고 하면 이 코드상 음수는 예외다. 하지만 문법적으로는 오류가 아니다. 그러나 프로그램 내용상에서는 사람의 나이이므로 오류가 맞다. 이러한 상황을 예외로 처리하기 위해서 예외 클래스를 직접 정의하였다.
    
    ```java
    if (age < 0) {
    	throw new ReadAgeException(); // 예외 발생
    }
    ```
    
    이렇게 예외 클래스의 인스턴스를 생성하고, 이를 대상으로 throw 선언을 하면 이로써 예외가 발생이 된다.
    
- 잘못된 catch 구문의 구성
    
    다음과 같이 세개의 예외 클래스가 정의 되었다고 가정해보자.
    
    ```java
    class FirstException extends Exception {...}
    class SecondException extends FirstEXception {...}
    class ThirdException extends SecondException {...}
    ```
    
    그리고 위의 세 종류 예외가 모두 발생 가능한 영역을 다음과 같이 try ~ catch 문으로 구성하였다고 가정해보자.
    
    ```java
    try {
    	....
    }
    catch (FirstException e) {...}
    catch (SecondException e) {...}
    catch (ThirdException e) {...}
    ```
    
    예외처리의 내용만 보면 문제가 없어 보이는데 컴파일 오류가 발생한다. 그리고 그 오류는 다음과 같다.
    
    “두 번째, 그리고 세 번째 catch 구문을 실행될 일이 절때 없습니다.”
    
    위 코드의 다음 catch 구문은 앞서 정의한 모든 예외의 인스턴스를 처리 할 수 있다.
    
    ```java
    catch (FirstException e) {...}
    ```
    
    예외 클래스 SecondException과 ThirdException이 FirstException을 직접 혹은 간접적으로 상속하고 있기 때문이다. 따라서 두 번째, 세 번째 catch 구문을 실행될 일은 없다. 따라서 위와 같이 catch 구문을 구성하고자 한다면 순서를 수정해야 한다.
    
    ```java
    try {
    	....
    }
    catch (ThirdException e) {...}
    catch (SecondException e) {...}
    catch (FirstException e) {...}
    ```
    
- finally 구문
    
    try이어서 finally 구문을 둘 수도 있다.
    
    ```java
    try {...
    }
    finally {... // 코드의 실행이 try 안으로 진입하면, 무조건 실행된다.
    }
    ```
    
    또는 다음과 같이 구성될 수도 있다.
    
    ```java
    try {...
    }
    catch (Exception name) {...
    }
    finally {... // 코드의 실행이 try 안으로 진입하면, 무조건 실행된다.
    }
    ```
    
    이렇게 등장하는 finally 구문은 코드의 실행이 try 안으로 진입하면 무조건 실행이 된다. try에서 예외가 발생하건 안 하건, catch가 실행되건 안되건, 무조건 실행된다. 그렇다면 finally 구문은 어떻게 유용하게 사용할 수 있을까? 앞서 다음 코드를 제시하였다. 그리고 파일을 생성하고 두 개의 문자를 저장하는 내용의 코드라는 정도만 언급하였다.
    
    ```java
    BufferedWriter writer = null;
    try {
        // 아래 문장에서 IOException 발생 가능
        writer = Files.newBufferedWriter(file);
    
        writer.write('A');     // IOException 발생 가능
        writer.write('Z');     // IOException 발생 가능
    
        if(writer != null)
            writer.close();     // IOException 발생 가능
    } 
    catch(IOException e) {
        e.printStackTrace();
    }
        
    ```
    
    위의 코드 중에서 다음 문장이 정상적으로 실행되면
    
    ```java
     writer = Files.newBufferedWriter(file);
    ```
    
    다음 문장을 무조건 실행이 되어여 한다.
    
    ```java
    writer.close();
    ```
    
    그런데 위의 코드에서 write 메소드를 호출하는 다음 두 문장 한 곳에서 예외가 발생하면, close 메소드의 호출이 생략되는 상황으로 이어져 문제가 생길 수 있다.
    
    ```java
    writer.write('A');
    writer.write('Z');
    ```
    
    그러나 다음과 같이 try ~ catch ~ finally문을 구성하면 이러한 문제를 해결할 수 있다.
    
    ```java
    import java.nio.file.Path;
    import java.nio.file.Paths;
    import java.nio.file.Files;
     
    import java.io.BufferedWriter;
    import java.io.IOException;
     
    class FinallyCase { 
        public static void main(String[] args) {
            Path file = Paths.get("C:\\\\javastudy\\\\Simple.txt");
    
            BufferedWriter writer = null;
    
            try {
                // 아래 문장에서 IOException 발생 가능
                writer = Files.newBufferedWriter(file);
    
                writer.write('A');     // IOException 발생 가능
                writer.write('Z');     // IOException 발생 가능
            } 
            catch(IOException e) {
                e.printStackTrace();
            }
            finally {
                if(writer != null)
                    writer.close();     // IOException 발생 가능
            }
        }
    }
    ```
    
    실행의 흐름이 try 안으로 들어오면 finally 구분은 반드시 실행되므로 위 예제의 close 메소드 호출은 보장이 된다. 그러나 위의 코드는 컴파일 에러가 발생한다. close의 호출문에서 IOException 예외가 발생할 수 있기 때문이다. 따라서 finally 구문을 다음과 같이 수정해야 한다. (코드가 복잡해지더라고 어쩔 수 없다.
    
    ```java
    try {...
    }
    catch (IOException e) {
    	e.printStackTrace();
    }
    finally {
    	try {
    		if (writer != null) {
    			writer.close();
    		}
    	}
    	catch (IOException e) {
    		e.printStackTrace();
    	}
    }
    ```
    
    이렇게 finally 내에서도 try ~ catch문을 작성할 수 있으며, 이 상황에서 이는 선택이 아니라 필수이다. 실제로 이러한 코드 구성이 이전에는 최선이었다. 하지만 자바7에서는 try-with-resources문이라는 것이 등장하면서 이 문자의 구성이 한결 단순해졌다.
    
- try-with-resources 구문
    
    앞서 다음의 문장이 정상적으로 실행이 되면 ,
    
    ```java
    writer = Files.newBufferWriter(file);
    ```
    
    다음 문장도 반드시 실행되어야 한다고 설명하였는데
    
    ```java
    writer.close();
    ```
    
    이러한 스타일의 코드 구성은 빈번하게 등장한다. 그런데 앞서 보였듯이 finally 구문으로 이를 처리할 경우 코드가 복잡해진다. 그러나 대부분은 catch 구문을 필요로 하기 때문에 기본 구성에 포함시켰다.
    
    ```java
    try (resource) {...
    }
    catch (Exception name) {...
    }
    ```
    
    위의 try 구문이 메소드처럼 보인다. 그러나 메소드가 아니고 메소드와 유사하게 동작하지도 않는다. 위의 문장에서 try에 이어 등장하는 소괄호 안에서는 종료의 과정을 필요로 하는 리소스 생성할 수 있다. 그러면 이 리소스는 try-with-resoutces문을 빠져나오면서 자동으로 종료가 된다. 다음 예제를 확인해보자.
    
    ```java
    import java.nio.file.Path;
    import java.nio.file.Paths;
    import java.nio.file.Files;
     
    import java.io.BufferedWriter;
    import java.io.IOException;
     
    class TryWithResource { 
        public static void main(String[] args) {
            Path file = Paths.get("C:\\\\javastudy\\\\Simple.txt");
    
            try(BufferedWriter writer = Files.newBufferedWriter(file);) {
                writer.write('A');     // IOException 발생 가능
                writer.write('Z');     // IOException 발생 가능
            } 
            catch(IOException e) {
                e.printStackTrace();
            }
        }
    }
    ```
    
    try안에서 예외가 발생하건 안 하건 writer를 대상으로 한 다음 메소드의 호출은 보장되기 때문이다.
    
    ```java
    writer.close(); // 직접 이 문장을 넣지 않아도 된다.
    ```
    
    그렇다면 리소스의 종료 관련 메소드가 close인 경우에만 자동으로 호출이 될까? 이에 대한 답은 인터페이스에서 찾을 수 있다.
    
    ```java
    java.lang.AutoCloseable
    ```
    
    이 인터페이스는 try-with-resources문에 의해 자동으로 종료되어야 할 리소스 관련 클래스가 반드시 구현되어야 하는 인터페이스이다. 그리고 이 인터페이스에는 다음 추상 메소드가 존재한다.
    
    ```java
    void colse() throws Exception
    ```
    
    즉 try-with-resources문에서 호출하는 메소드는 AutoCloseable 인터페이스의 close 메소드이다. 따라서 close 이외의 메소드 호출을 기대하는 것은 곤란한다. 그리고 다음과 같이 둘 이상의 리소스에 대해서도 try-with-resources문을 구성할 수 있다. 세미콜론으로 리소스를 구분하면 된다.
    
    ```java
    try (resources1; resources2) {...
    }
    catch (Exception name) {...
    }
    ```
    
    - 예외처리는 성능의 저하로 이어진다.
        
        try 구문 안에 위치한 코드는 try 구문 밖에 위치한 코드에 비해 실행 속도가 느리다. 따라서 과도한 예외처리는 심각한 성능의 저하로 이어질 수 있다. 따라서 예외처리가 불필요한 코드를 try 구문 안에 두는 일을 자제해야 한다. 참고로 모든 예외를 민감하게 처리하는 프로그램은 생각보다 많지 않다. 규모가 클수록, 성능이 중요시 될수록 try~catch문 이외의 다양한 방법으로 그리고 선별적으로 예외를 처리한다.